Workbook

Sheet Instructions
A1: CHARGEBACK DEFENDER — DISPUTE RESPONSE TRACKER
A2: Operational control centre — disputes, deadlines, evidence, outcomes, rate monitoring
A3: TAB | B3: PURPOSE
A4: Instructions | B4: You are here. Read before using the Tracker.
A5: Dispute Log | B5: Log every dispute: intake, triage, evidence, submission, outcome. Three auto-columns drive next actions.
A6: Rate Monitor | B6: Track monthly chargeback rate vs. processor thresholds. Chargebacks-to-Breach updates automatically.
A7: Learning Loop | B7: Post-resolution review. Record what was missing. Stops you losing the same dispute twice.
A9: STEP | B9: ACTION
A10: STEP 1 | B10: When a dispute arrives — open Dispute Log and log it immediately. Enter Dispute Ref, Date Received, Deadline, Processor, Card Network, Reason Code, and Dispute Type.
A11: STEP 2 | B11: Cols L, M, N update automatically. L = Next Action. M = Evidence Checklist for your dispute type. N = Template to use. These update at every stage as you fill the row.
A12: STEP 3 | B12: Run the Fight-or-Flight Calculator (separate file). Enter your decision (Fight / Accept) in col K. Next Action updates.
A13: STEP 4 | B13: Gather evidence per col M checklist. Tick cols O–R as you complete each category. Set col S to "Yes" when evidence is ready — Next Action will prompt you to submit.
A14: STEP 5 | B14: Submit the response. Record submission date (col T) and confirmation number (col U). Next Action shows "Awaiting decision."
A15: STEP 6 | B15: When outcome arrives — log Win/Loss/Accepted in col V. For every Loss — complete a Learning Loop row.
A16: STEP 7 | B16: Update Rate Monitor monthly. Shows proximity to processor thresholds and chargebacks remaining until breach.
A18: DISCLAIMER: Educational workflow tool only. Not legal advice. No guarantee of dispute outcome. Verify current processor thresholds and deadlines — these change.

Sheet Checkpoints
A1: CHARGEBACK DEFENDER — CHECKPOINT STATUS DASHBOARD
A2: Live view of all disputes. Checkpoints update automatically from Dispute Log. A dispute is ready to submit when Checkpoints 1, 2, and 3 all show ✓ CLEAR.
A3: ✓ CLEAR = checkpoint passed ✗ BLOCKED = criteria not met READY = evidence done, submit now N/A = accepted, no response needed
A4: # | B4: DISPUTE REF | C4: DISPUTE TYPE | CE 3.0 CONDITIONAL: If dispute type is Fraud - Card Not Present (Visa 10.4) on Stripe or Shopify Payments, all 7 CE 3.0 fields must be captured: IP address, Device ID / fingerprint, Customer email address, Customer activity log, 2 prior transactions from the same customer, Delivery confirmation, Order confirmation | D4: DAYS LEFT | E4: DECISION | F4: DEADLINE | G4: CHECKPOINT 1 INTAKE | H4: CHECKPOINT 2 EVIDENCE | I4: CHECKPOINT 3 SUBMIT | J4: NEXT ACTION
A5: OPEN DISPUTES — auto-populated from Dispute Log
A6: Rows without a dispute reference (col A of Dispute Log) are hidden automatically via conditional formatting.
A7: 1 | B7: ='Dispute Log'!A6 | C7: ='Dispute Log'!H6 | D7: ='Dispute Log'!D6 | E7: ='Dispute Log'!K6 | F7: ='Dispute Log'!C6 | G7: ='Dispute Log'!Z6 | H7: ='Dispute Log'!AA6 | I7: ='Dispute Log'!AB6 | J7: ='Dispute Log'!L6
A8: 2 | B8: ='Dispute Log'!A7 | C8: ='Dispute Log'!H7 | D8: ='Dispute Log'!D7 | E8: ='Dispute Log'!K7 | F8: ='Dispute Log'!C7 | G8: ='Dispute Log'!Z7 | H8: ='Dispute Log'!AA7 | I8: ='Dispute Log'!AB7 | J8: ='Dispute Log'!L7
A9: 3 | B9: ='Dispute Log'!A8 | C9: ='Dispute Log'!H8 | D9: ='Dispute Log'!D8 | E9: ='Dispute Log'!K8 | F9: ='Dispute Log'!C8 | G9: ='Dispute Log'!Z8 | H9: ='Dispute Log'!AA8 | I9: ='Dispute Log'!AB8 | J9: ='Dispute Log'!L8
A10: 4 | B10: ='Dispute Log'!A9 | C10: ='Dispute Log'!H9 | D10: ='Dispute Log'!D9 | E10: ='Dispute Log'!K9 | F10: ='Dispute Log'!C9 | G10: ='Dispute Log'!Z9 | H10: ='Dispute Log'!AA9 | I10: ='Dispute Log'!AB9 | J10: ='Dispute Log'!L9
A11: 5 | B11: ='Dispute Log'!A10 | C11: ='Dispute Log'!H10 | D11: ='Dispute Log'!D10 | E11: ='Dispute Log'!K10 | F11: ='Dispute Log'!C10 | G11: ='Dispute Log'!Z10 | H11: ='Dispute Log'!AA10 | I11: ='Dispute Log'!AB10 | J11: ='Dispute Log'!L10
A12: 6 | B12: ='Dispute Log'!A11 | C12: ='Dispute Log'!H11 | D12: ='Dispute Log'!D11 | E12: ='Dispute Log'!K11 | F12: ='Dispute Log'!C11 | G12: ='Dispute Log'!Z11 | H12: ='Dispute Log'!AA11 | I12: ='Dispute Log'!AB11 | J12: ='Dispute Log'!L11
A13: 7 | B13: ='Dispute Log'!A12 | C13: ='Dispute Log'!H12 | D13: ='Dispute Log'!D12 | E13: ='Dispute Log'!K12 | F13: ='Dispute Log'!C12 | G13: ='Dispute Log'!Z12 | H13: ='Dispute Log'!AA12 | I13: ='Dispute Log'!AB12 | J13: ='Dispute Log'!L12
A14: 8 | B14: ='Dispute Log'!A13 | C14: ='Dispute Log'!H13 | D14: ='Dispute Log'!D13 | E14: ='Dispute Log'!K13 | F14: ='Dispute Log'!C13 | G14: ='Dispute Log'!Z13 | H14: ='Dispute Log'!AA13 | I14: ='Dispute Log'!AB13 | J14: ='Dispute Log'!L13
A15: 9 | B15: ='Dispute Log'!A14 | C15: ='Dispute Log'!H14 | D15: ='Dispute Log'!D14 | E15: ='Dispute Log'!K14 | F15: ='Dispute Log'!C14 | G15: ='Dispute Log'!Z14 | H15: ='Dispute Log'!AA14 | I15: ='Dispute Log'!AB14 | J15: ='Dispute Log'!L14
A16: 10 | B16: ='Dispute Log'!A15 | C16: ='Dispute Log'!H15 | D16: ='Dispute Log'!D15 | E16: ='Dispute Log'!K15 | F16: ='Dispute Log'!C15 | G16: ='Dispute Log'!Z15 | H16: ='Dispute Log'!AA15 | I16: ='Dispute Log'!AB15 | J16: ='Dispute Log'!L15
A17: 11 | B17: ='Dispute Log'!A16 | C17: ='Dispute Log'!H16 | D17: ='Dispute Log'!D16 | E17: ='Dispute Log'!K16 | F17: ='Dispute Log'!C16 | G17: ='Dispute Log'!Z16 | H17: ='Dispute Log'!AA16 | I17: ='Dispute Log'!AB16 | J17: ='Dispute Log'!L16
A18: 12 | B18: ='Dispute Log'!A17 | C18: ='Dispute Log'!H17 | D18: ='Dispute Log'!D17 | E18: ='Dispute Log'!K17 | F18: ='Dispute Log'!C17 | G18: ='Dispute Log'!Z17 | H18: ='Dispute Log'!AA17 | I18: ='Dispute Log'!AB17 | J18: ='Dispute Log'!L17
... A27: 21 | B27: ='Dispute Log'!A26 | C27: ='Dispute Log'!H26 | D27: ='Dispute Log'!D26 | E27: ='Dispute Log'!K26 | F27: ='Dispute Log'!C26 | G27: ='Dispute Log'!Z26 | H27: ='Dispute Log'!AA26 | I27: ='Dispute Log'!AB26 | J27: ='Dispute Log'!L26
A29: CHECKPOINT CRITERIA
A30: CHECKPOINT 1 — INTAKE COMPLETE | C30: Dispute Ref + Date Received + Deadline + Processor + Card Network + Reason Code + Dispute Type + Decision all filled AND AUTO columns L, M, N are populated (not blank)
A31: CHECKPOINT 2 — EVIDENCE MINIMUM MET | C31: Checkpoint 1 clear AND all must-have evidence for the dispute type gathered (Tracker col M) AND all files named per TYPE_ORDERREF_YYYYMMDD convention AND total file count ≤10 AND Evidence Complete = Yes in col S | CE 3.0 CONDITIONAL: If dispute type is Fraud - Card Not Present (Visa 10.4) on Stripe or Shopify Payments, all 7 CE 3.0 fields must be captured: IP address, Device ID / fingerprint, Customer email address, Customer activity log, 2 prior transactions from the same customer, Delivery confirmation, Order confirmation
A32: CHECKPOINT 3 — SUBMISSION READY | C32: Checkpoint 2 clear AND written response drafted using correct Template Library entry (Tracker col N) AND Dispute Response Cover Sheet completed (all 7 sections) AND deadline confirmed in processor portal AND submitting via correct portal

Sheet Dispute Log
A1: CHARGEBACK DEFENDER — DISPUTE RESPONSE TRACKER
A2: Log every dispute the day it arrives. AUTO columns L–N drive next actions. Checkpoint columns Z–AB show submission readiness.
A3: INTAKE & TRIAGE | K3: DECISION | L3: AUTO: NEXT STEPS (do not edit) | O3: EVIDENCE | T3: SUBMISSION | V3: OUTCOME | Y3: NOTES | Z3: CHECKPOINTS
L4: Read-only — auto-generated from your inputs
A5: DISPUTE REF | B5: DATE RECEIVED | C5: RESPONSE DEADLINE | D5: DAYS REMAINING | E5: PROCESSOR | F5: CARD NETWORK | G5: REASON CODE | H5: DISPUTE TYPE | I5: TRANSACTION AMOUNT | J5: DISPUTE FEE | K5: FIGHT / ACCEPT | L5: NEXT ACTION (auto) | M5: EVIDENCE CHECKLIST (auto) | N5: TEMPLATE (auto) | O5: ORDER DETAILS | P5: DELIVERY PROOF | Q5: IP / DEVICE ID | R5: CUSTOMER COMMS | S5: EVIDENCE COMPLETE | T5: SUBMITTED DATE | U5: SUBMISSION REF | V5: OUTCOME | W5: OUTCOME DATE | X5: NET RESULT ($) | Y5: NOTES | Z5: CHECKPOINT 1 INTAKE | AA5: CHECKPOINT 2 EVIDENCE | AB5: CHECKPOINT 3 SUBMIT
D6: =IF(C6="","",C6-TODAY()) | L6: =IF(B6="","→ Enter dispute details to begin",IF(K6="","→ Run Fight-or-Flight Calculator → enter decision in col K",IF(K6="Accept","✓ Accepted — log in Learning Loop if instructive",IF(V6<>"","✓ Resolved: "&V6&" — complete Learning Loop row",IF(T6<>"","→ Awaiting processor decision — monitor portal",IF(S6="Yes","→ Submit via "&IF(E6="Stripe","Stripe Dashboard → Disputes",IF(E6="Shopify Payments","Shopify Admin → Orders → Chargebacks","PayPal Resolution Centre")),IF(AND(ISNUMBER(D6),D6<=3),"⚠ URGENT: "&D6&" days left — submit NOW",IF(ISNUMBER(D6),"→ Gather evidence (col M) — "&D6&" days remaining","→ Gather evidence per checklist in col M")))))))) | M6: =IF(H6="","—",IF(OR(ISNUMBER(SEARCH("Fraud",H6)),ISNUMBER(SEARCH("Card Not Present",H6))),"✦ IP address at checkout ✦ Customer email address"&CHAR(10)&"✦ Device ID / fingerprint"&CHAR(10)&"✦ Prior transactions x2"&CHAR(10)&"✦ Delivery confirmation"&CHAR(10)&"✦ Order confirmation"&CHAR(10)&"✦ Customer activity log",IF(OR(ISNUMBER(SEARCH("Not Received",H6)),ISNUMBER(SEARCH("INR",H6))),"✦ Carrier proof of delivery (PDF)"&CHAR(10)&"✦ Tracking number + carrier"&CHAR(10)&"✦ Shipping confirmation email"&CHAR(10)&"✦ Order confirmation",IF(OR(ISNUMBER(SEARCH("Not as Described",H6)),ISNUMBER(SEARCH("SNAD",H6))),"✦ Product listing screenshot"&CHAR(10)&"✦ Order confirmation"&CHAR(10)&"✦ Product photos (as shipped)"&CHAR(10)&"✦ Customer support thread",IF(ISNUMBER(SEARCH("Credit",H6)),"✦ Refund confirmation + timestamp"&CHAR(10)&"✦ Order confirmation"&CHAR(10)&"✦ Customer communication",IF(OR(ISNUMBER(SEARCH("Amex",H6)),ISNUMBER(SEARCH("Inquiry",H6))),"✦ Order confirmation"&CHAR(10)&"✦ Customer communication"&CHAR(10)&"✦ Delivery confirmation"&CHAR(10)&"✦ Product/service description",IF(ISNUMBER(SEARCH("Subscription",H6)),"✦ Subscription terms at sign-up"&CHAR(10)&"✦ Cancellation policy"&CHAR(10)&"✦ No cancellation received proof",IF(ISNUMBER(SEARCH("Digital",H6)),"✦ Digital delivery confirmation"&CHAR(10)&"✦ Access / usage logs"&CHAR(10)&"✦ Order confirmation","✦ Order confirmation"&CHAR(10)&"✦ Delivery confirmation"&CHAR(10)&"✦ Customer support thread"&CHAR(10)&"✦ Checkout terms screenshot")))))))) | N6: =IF(H6="","—",IF(OR(ISNUMBER(SEARCH("Fraud",H6)),ISNUMBER(SEARCH("Card Not Present",H6))),"T1 — Fraud / Card Not Present",IF(OR(ISNUMBER(SEARCH("Not Received",H6)),ISNUMBER(SEARCH("INR",H6))),"T2 — Item Not Received",IF(OR(ISNUMBER(SEARCH("Not as Described",H6)),ISNUMBER(SEARCH("SNAD",H6))),"T3 — Not as Described",IF(ISNUMBER(SEARCH("Credit",H6)),"T4 — Credit Not Processed",IF(ISNUMBER(SEARCH("Subscription",H6)),"T5 — Subscription Cancelled",IF(ISNUMBER(SEARCH("Digital",H6)),"T6 — Digital Goods Not Delivered",IF(OR(ISNUMBER(SEARCH("Amex",H6)),ISNUMBER(SEARCH("Inquiry",H6))),"T7 — Amex / Inquiry","T7 — General / Other")))))))) | X6: =IF(V6="Win",I6-J6,IF(OR(V6="Accepted",V6="Withdrawn"),-J6,IF(V6="Loss",-I6-J6,""))) | Z6: =IF(B6="","—",IF(AND(A6<>"",B6<>"",C6<>"",E6<>"",F6<>"",G6<>"",H6<>"",K6<>""),"✓ CLEAR","✗ BLOCKED")) | AA6: =IF(B6="","—",IF(K6="Accept","N/A — Accepted",IF(AND(A6<>"",B6<>"",C6<>"",E6<>"",F6<>"",G6<>"",H6<>"",K6<>""),IF(S6="Yes","✓ CLEAR","✗ BLOCKED"),"— Checkpoint 1 first"))) | AB6: =IF(B6="","—",IF(K6="Accept","N/A — Accepted",IF(V6<>"","✓ RESOLVED: "&V6,IF(T6<>"","✓ SUBMITTED",IF(S6="Yes","READY — submit now","✗ BLOCKED")))))
D7: =IF(C7="","",C7-TODAY()) | L7: =IF(B7="","→ Enter dispute details to begin",IF(K7="","→ Run Fight-or-Flight Calculator → enter decision in col K",IF(K7="Accept","✓ Accepted — log in Learning Loop if instructive",IF(V7<>"","✓ Resolved: "&V7&" — complete Learning Loop row",IF(T7<>"","→ Awaiting processor decision — monitor portal",IF(S7="Yes","→ Submit via "&IF(E7="Stripe","Stripe Dashboard → Disputes",IF(E7="Shopify Payments","Shopify Admin → Orders → Chargebacks","PayPal Resolution Centre")),IF(AND(ISNUMBER(D7),D7<=3),"⚠ URGENT: "&D7&" days left — submit NOW",IF(ISNUMBER(D7),"→ Gather evidence (col M) — "&D7&" days remaining","→ Gather evidence per checklist in col M")))))))) | M7: =IF(H7="","—",IF(OR(ISNUMBER(SEARCH("Fraud",H7)),ISNUMBER(SEARCH("Card Not Present",H7))),"✦ IP address at checkout"&CHAR(10)&"✦ Device ID / fingerprint"&CHAR(10)&"✦ Prior transactions x2"&CHAR(10)&"✦ Delivery confirmation"&CHAR(10)&"✦ Order confirmation"&CHAR(10)&"✦ Customer activity log",IF(OR(ISNUMBER(SEARCH("Not Received",H7)),ISNUMBER(SEARCH("INR",H7))),"✦ Carrier proof of delivery (PDF)"&CHAR(10)&"✦ Tracking number + carrier"&CHAR(10)&"✦ Shipping confirmation email"&CHAR(10)&"✦ Order confirmation",IF(OR(ISNUMBER(SEARCH("Not as Described",H7)),ISNUMBER(SEARCH("SNAD",H7))),"✦ Product listing screenshot"&CHAR(10)&"✦ Order confirmation"&CHAR(10)&"✦ Product photos (as shipped)"&CHAR(10)&"✦ Customer support thread",IF(ISNUMBER(SEARCH("Credit",H7)),"✦ Refund confirmation + timestamp"&CHAR(10)&"✦ Order confirmation"&CHAR(10)&"✦ Customer communication",IF(ISNUMBER(SEARCH("Duplicate",H7)),"✦ Transaction records (single charge)"&CHAR(10)&"✦ Order confirmation"&CHAR(10)&"✦ Processor payment history",IF(ISNUMBER(SEARCH("Subscription",H7)),"✦ Subscription terms at sign-up"&CHAR(10)&"✦ Cancellation policy"&CHAR(10)&"✦ No cancellation received proof",IF(ISNUMBER(SEARCH("Digital",H7)),"✦ Digital delivery confirmation"&CHAR(10)&"✦ Access / usage logs"&CHAR(10)&"✦ Order confirmation","✦ Order confirmation"&CHAR(10)&"✦ Delivery confirmation"&CHAR(10)&"✦ Customer support thread"&CHAR(10)&"✦ Checkout terms screenshot")))))))) | N7: =IF(H7="","—",IF(OR(ISNUMBER(SEARCH("Fraud",H7)),ISNUMBER(SEARCH("Card Not Present",H7))),"T1 — Fraud / Card Not Present",IF(OR(ISNUMBER(SEARCH("Not Received",H7)),ISNUMBER(SEARCH("INR",H7))),"T2 — Item Not Received",IF(OR(ISNUMBER(SEARCH("Not as Described",H7)),ISNUMBER(SEARCH("SNAD",H7))),"T3 — Not as Described",IF(ISNUMBER(SEARCH("Credit",H7)),"T4 — Credit Not Processed",IF(ISNUMBER(SEARCH("Subscription",H7)),"T5 — Subscription Cancelled",IF(ISNUMBER(SEARCH("Digital",H7)),"T6 — Digital Goods Not Delivered",IF(OR(ISNUMBER(SEARCH("Amex",H7)),ISNUMBER(SEARCH("Inquiry",H7))),"T7 — Amex / Inquiry","T7 — General / Other")))))))) | X7: =IF(V7="Win",I7-J7,IF(OR(V7="Accepted",V7="Withdrawn"),-J7,IF(V7="Loss",-I7-J7,""))) | Z7: =IF(B7="","—",IF(AND(A7<>"",B7<>"",C7<>"",E7<>"",F7<>"",G7<>"",H7<>"",K7<>""),"✓ CLEAR","✗ BLOCKED")) | AA7: =IF(B7="","—",IF(K7="Accept","N/A — Accepted",IF(AND(A7<>"",B7<>"",C7<>"",E7<>"",F7<>"",G7<>"",H7<>"",K7<>""),IF(S7="Yes","✓ CLEAR","✗ BLOCKED"),"— Checkpoint 1 first"))) | AB7: =IF(B7="","—",IF(K7="Accept","N/A — Accepted",IF(V7<>"","✓ RESOLVED: "&V7,IF(T7<>"","✓ SUBMITTED",IF(S7="Yes","READY — submit now","✗ BLOCKED")))))
D8: =IF(C8="","",C8-TODAY()) | L8: =IF(B8="","→ Enter dispute details to begin",IF(K8="","→ Run Fight-or-Flight Calculator → enter decision in col K",IF(K8="Accept","✓ Accepted — log in Learning Loop if instructive",IF(V8<>"","✓ Resolved: "&V8&" — complete Learning Loop row",IF(T8<>"","→ Awaiting processor decision — monitor portal",IF(S8="Yes","→ Submit via "&IF(E8="Stripe","Stripe Dashboard → Disputes",IF(E8="Shopify Payments","Shopify Admin → Orders → Chargebacks","PayPal Resolution Centre")),IF(AND(ISNUMBER(D8),D8<=3),"⚠ URGENT: "&D8&" days left — submit NOW",IF(ISNUMBER(D8),"→ Gather evidence (col M) — "&D8&" days remaining","→ Gather evidence per checklist in col M")))))))) | M8: =IF(H8="","—",IF(OR(ISNUMBER(SEARCH("Fraud",H8)),ISNUMBER(SEARCH("Card Not Present",H8))),"✦ IP address at checkout"&CHAR(10)&"✦ Device ID / fingerprint"&CHAR(10)&"✦ Prior transactions x2"&CHAR(10)&"✦ Delivery confirmation"&CHAR(10)&"✦ Order confirmation"&CHAR(10)&"✦ Customer activity log",IF(OR(ISNUMBER(SEARCH("Not Received",H8)),ISNUMBER(SEARCH("INR",H8))),"✦ Carrier proof of delivery (PDF)"&CHAR(10)&"✦ Tracking number + carrier"&CHAR(10)&"✦ Shipping confirmation email"&CHAR(10)&"✦ Order confirmation",IF(OR(ISNUMBER(SEARCH("Not as Described",H8)),ISNUMBER(SEARCH("SNAD",H8))),"✦ Product listing screenshot"&CHAR(10)&"✦ Order confirmation"&CHAR(10)&"✦ Product photos (as shipped)"&CHAR(10)&"✦ Customer support thread",IF(ISNUMBER(SEARCH("Credit",H8)),"✦ Refund confirmation + timestamp"&CHAR(10)&"✦ Order confirmation"&CHAR(10)&"✦ Customer communication",IF(ISNUMBER(SEARCH("Duplicate",H8)),"✦ Transaction records (single charge)"&CHAR(10)&"✦ Order confirmation"&CHAR(10)&"✦ Processor payment history",IF(ISNUMBER(SEARCH("Subscription",H8)),"✦ Subscription terms at sign-up"&CHAR(10)&"✦ Cancellation policy"&CHAR(10)&"✦ No cancellation received proof",IF(ISNUMBER(SEARCH("Digital",H8)),"✦ Digital delivery confirmation"&CHAR(10)&"✦ Access / usage logs"&CHAR(10)&"✦ Order confirmation","✦ Order confirmation"&CHAR(10)&"✦ Delivery confirmation"&CHAR(10)&"✦ Customer support thread"&CHAR(10)&"✦ Checkout terms screenshot")))))))) | N8: =IF(H8="","—",IF(OR(ISNUMBER(SEARCH("Fraud",H8)),ISNUMBER(SEARCH("Card Not Present",H8))),"T1 — Fraud / Card Not Present",IF(OR(ISNUMBER(SEARCH("Not Received",H8)),ISNUMBER(SEARCH("INR",H8))),"T2 — Item Not Received",IF(OR(ISNUMBER(SEARCH("Not as Described",H8)),ISNUMBER(SEARCH("SNAD",H8))),"T3 — Not as Described",IF(ISNUMBER(SEARCH("Credit",H8)),"T4 — Credit Not Processed",IF(ISNUMBER(SEARCH("Subscription",H8)),"T5 — Subscription Cancelled",IF(ISNUMBER(SEARCH("Digital",H8)),"T6 — Digital Goods Not Delivered",IF(OR(ISNUMBER(SEARCH("Amex",H8)),ISNUMBER(SEARCH("Inquiry",H8))),"T7 — Amex / Inquiry","T7 — General / Other")))))))) | X8: =IF(V8="Win",I8-J8,IF(OR(V8="Accepted",V8="Withdrawn"),-J8,IF(V8="Loss",-I8-J8,""))) | Z8: =IF(B8="","—",IF(AND(A8<>"",B8<>"",C8<>"",E8<>"",F8<>"",G8<>"",H8<>"",K8<>""),"✓ CLEAR","✗ BLOCKED")) | AA8: =IF(B8="","—",IF(K8="Accept","N/A — Accepted",IF(AND(A8<>"",B8<>"",C8<>"",E8<>"",F8<>"",G8<>"",H8<>"",K8<>""),IF(S8="Yes","✓ CLEAR","✗ BLOCKED"),"— Checkpoint 1 first"))) | AB8: =IF(B8="","—",IF(K8="Accept","N/A — Accepted",IF(V8<>"","✓ RESOLVED: "&V8,IF(T8<>"","✓ SUBMITTED",IF(S8="Yes","READY — submit now","✗ BLOCKED")))))
D9: =IF(C9="","",C9-TODAY()) | L9: =IF(B9="","→ Enter dispute details to begin",IF(K9="","→ Run Fight-or-Flight Calculator → enter decision in col K",IF(K9="Accept","✓ Accepted — log in Learning Loop if instructive",IF(V9<>"","✓ Resolved: "&V9&" — complete Learning Loop row",IF(T9<>"","→ Awaiting processor decision — monitor portal",IF(S9="Yes","→ Submit via "&IF(E9="Stripe","Stripe Dashboard → Disputes",IF(E9="Shopify Payments","Shopify Admin → Orders → Chargebacks","PayPal Resolution Centre")),IF(AND(ISNUMBER(D9),D9<=3),"⚠ URGENT: "&D9&" days left — submit NOW",IF(ISNUMBER(D9),"→ Gather evidence (col M) — "&D9&" days remaining","→ Gather evidence per checklist in col M")))))))) | M9: =IF(H9="","—",IF(OR(ISNUMBER(SEARCH("Fraud",H9)),ISNUMBER(SEARCH("Card Not Present",H9))),"✦ IP address at checkout"&CHAR(10)&"✦ Device ID / fingerprint"&CHAR(10)&"✦ Prior transactions x2"&CHAR(10)&"✦ Delivery confirmation"&CHAR(10)&"✦ Order confirmation"&CHAR(10)&"✦ Customer activity log",IF(OR(ISNUMBER(SEARCH("Not Received",H9)),ISNUMBER(SEARCH("INR",H9))),"✦ Carrier proof of delivery (PDF)"&CHAR(10)&"✦ Tracking number + carrier"&CHAR(10)&"✦ Shipping confirmation email"&CHAR(10)&"✦ Order confirmation",IF(OR(ISNUMBER(SEARCH("Not as Described",H9)),ISNUMBER(SEARCH("SNAD",H9))),"✦ Product listing screenshot"&CHAR(10)&"✦ Order confirmation"&CHAR(10)&"✦ Product photos (as shipped)"&CHAR(10)&"✦ Customer support thread",IF(ISNUMBER(SEARCH("Credit",H9)),"✦ Refund confirmation + timestamp"&CHAR(10)&"✦ Order confirmation"&CHAR(10)&"✦ Customer communication",IF(ISNUMBER(SEARCH("Duplicate",H9)),"✦ Transaction records (single charge)"&CHAR(10)&"✦ Order confirmation"&CHAR(10)&"✦ Processor payment history",IF(ISNUMBER(SEARCH("Subscription",H9)),"✦ Subscription terms at sign-up"&CHAR(10)&"✦ Cancellation policy"&CHAR(10)&"✦ No cancellation received proof",IF(ISNUMBER(SEARCH("Digital",H9)),"✦ Digital delivery confirmation"&CHAR(10)&"✦ Access / usage logs"&CHAR(10)&"✦ Order confirmation","✦ Order confirmation"&CHAR(10)&"✦ Delivery confirmation"&CHAR(10)&"✦ Customer support thread"&CHAR(10)&"✦ Checkout terms screenshot")))))))) | N9: =IF(H9="","—",IF(OR(ISNUMBER(SEARCH("Fraud",H9)),ISNUMBER(SEARCH("Card Not Present",H9))),"T1 — Fraud / Card Not Present",IF(OR(ISNUMBER(SEARCH("Not Received",H9)),ISNUMBER(SEARCH("INR",H9))),"T2 — Item Not Received",IF(OR(ISNUMBER(SEARCH("Not as Described",H9)),ISNUMBER(SEARCH("SNAD",H9))),"T3 — Not as Described",IF(ISNUMBER(SEARCH("Credit",H9)),"T4 — Credit Not Processed",IF(ISNUMBER(SEARCH("Subscription",H9)),"T5 — Subscription Cancelled",IF(ISNUMBER(SEARCH("Digital",H9)),"T6 — Digital Goods Not Delivered",IF(OR(ISNUMBER(SEARCH("Amex",H9)),ISNUMBER(SEARCH("Inquiry",H9))),"T7 — Amex / Inquiry","T7 — General / Other")))))))) | X9: =IF(V9="Win",I9-J9,IF(OR(V9="Accepted",V9="Withdrawn"),-J9,IF(V9="Loss",-I9-J9,""))) | Z9: =IF(B9="","—",IF(AND(A9<>"",B9<>"",C9<>"",E9<>"",F9<>"",G9<>"",H9<>"",K9<>""),"✓ CLEAR","✗ BLOCKED")) | AA9: =IF(B9="","—",IF(K9="Accept","N/A — Accepted",IF(AND(A9<>"",B9<>"",C9<>"",E9<>"",F9<>"",G9<>"",H9<>"",K9<>""),IF(S9="Yes","✓ CLEAR","✗ BLOCKED"),"— Checkpoint 1 first"))) | AB9: =IF(B9="","—",IF(K9="Accept","N/A — Accepted",IF(V9<>"","✓ RESOLVED: "&V9,IF(T9<>"","✓ SUBMITTED",IF(S9="Yes","READY — submit now","✗ BLOCKED")))))
D10: =IF(C10="","",C10-TODAY()) | L10: =IF(B10="","→ Enter dispute details to begin",IF(K10="","→ Run Fight-or-Flight Calculator → enter decision in col K",IF(K10="Accept","✓ Accepted — log in Learning Loop if instructive",IF(V10<>"","✓ Resolved: "&V10&" — complete Learning Loop row",IF(T10<>"","→ Awaiting processor decision — monitor portal",IF(S10="Yes","→ Submit via "&IF(E10="Stripe","Stripe Dashboard → Disputes",IF(E10="Shopify Payments","Shopify Admin → Orders → Chargebacks","PayPal Resolution Centre")),IF(AND(ISNUMBER(D10),D10<=3),"⚠ URGENT: "&D10&" days left — submit NOW",IF(ISNUMBER(D10),"→ Gather evidence (col M) — "&D10&" days remaining","→ Gather evidence per checklist in col M")))))))) | M10: =IF(H10="","—",IF(OR(ISNUMBER(SEARCH("Fraud",H10)),ISNUMBER(SEARCH("Card Not Present",H10))),"✦ IP address at checkout"&CHAR(10)&"✦ Device ID / fingerprint"&CHAR(10)&"✦ Prior transactions x2"&CHAR(10)&"✦ Delivery confirmation"&CHAR(10)&"✦ Order confirmation"&CHAR(10)&"✦ Customer activity log",IF(OR(ISNUMBER(SEARCH("Not Received",H10)),ISNUMBER(SEARCH("INR",H10))),"✦ Carrier proof of delivery (PDF)"&CHAR(10)&"✦ Tracking number + carrier"&CHAR(10)&"✦ Shipping confirmation email"&CHAR(10)&"✦ Order confirmation",IF(OR(ISNUMBER(SEARCH("Not as Described",H10)),ISNUMBER(SEARCH("SNAD",H10))),"✦ Product listing screenshot"&CHAR(10)&"✦ Order confirmation"&CHAR(10)&"✦ Product photos (as shipped)"&CHAR(10)&"✦ Customer support thread",IF(ISNUMBER(SEARCH("Credit",H10)),"✦ Refund confirmation + timestamp"&CHAR(10)&"✦ Order confirmation"&CHAR(10)&"✦ Customer communication",IF(ISNUMBER(SEARCH("Duplicate",H10)),"✦ Transaction records (single charge)"&CHAR(10)&"✦ Order confirmation"&CHAR(10)&"✦ Processor payment history",IF(ISNUMBER(SEARCH("Subscription",H10)),"✦ Subscription terms at sign-up"&CHAR(10)&"✦ Cancellation policy"&CHAR(10)&"✦ No cancellation received proof",IF(ISNUMBER(SEARCH("Digital",H10)),"✦ Digital delivery confirmation"&CHAR(10)&"✦ Access / usage logs"&CHAR(10)&"✦ Order confirmation","✦ Order confirmation"&CHAR(10)&"✦ Delivery confirmation"&CHAR(10)&"✦ Customer support thread"&CHAR(10)&"✦ Checkout terms screenshot")))))))) | N10: =IF(H10="","—",IF(OR(ISNUMBER(SEARCH("Fraud",H10)),ISNUMBER(SEARCH("Card Not Present",H10))),"T1 — Fraud / Card Not Present",IF(OR(ISNUMBER(SEARCH("Not Received",H10)),ISNUMBER(SEARCH("INR",H10))),"T2 — Item Not Received",IF(OR(ISNUMBER(SEARCH("Not as Described",H10)),ISNUMBER(SEARCH("SNAD",H10))),"T3 — Not as Described",IF(ISNUMBER(SEARCH("Credit",H10)),"T4 — Credit Not Processed",IF(ISNUMBER(SEARCH("Subscription",H10)),"T5 — Subscription Cancelled",IF(ISNUMBER(SEARCH("Digital",H10)),"T6 — Digital Goods Not Delivered",IF(OR(ISNUMBER(SEARCH("Amex",H10)),ISNUMBER(SEARCH("Inquiry",H10))),"T7 — Amex / Inquiry","T7 — General / Other")))))))) | X10: =IF(V10="Win",I10-J10,IF(OR(V10="Accepted",V10="Withdrawn"),-J10,IF(V10="Loss",-I10-J10,""))) | Z10: =IF(B10="","—",IF(AND(A10<>"",B10<>"",C10<>"",E10<>"",F10<>"",G10<>"",H10<>"",K10<>""),"✓ CLEAR","✗ BLOCKED")) | AA10: =IF(B10="","—",IF(K10="Accept","N/A — Accepted",IF(AND(A10<>"",B10<>"",C10<>"",E10<>"",F10<>"",G10<>"",H10<>"",K10<>""),IF(S10="Yes","✓ CLEAR","✗ BLOCKED"),"— Checkpoint 1 first"))) | AB10: =IF(B10="","—",IF(K10="Accept","N/A — Accepted",IF(V10<>"","✓ RESOLVED: "&V10,IF(T10<>"","✓ SUBMITTED",IF(S10="Yes","READY — submit now","✗ BLOCKED")))))
D11: =IF(C11="","",C11-TODAY()) | L11: =IF(B11="","→ Enter dispute details to begin",IF(K11="","→ Run Fight-or-Flight Calculator → enter decision in col K",IF(K11="Accept","✓ Accepted — log in Learning Loop if instructive",IF(V11<>"","✓ Resolved: "&V11&" — complete Learning Loop row",IF(T11<>"","→ Awaiting processor decision — monitor portal",IF(S11="Yes","→ Submit via "&IF(E11="Stripe","Stripe Dashboard → Disputes",IF(E11="Shopify Payments","Shopify Admin → Orders → Chargebacks","PayPal Resolution Centre")),IF(AND(ISNUMBER(D11),D11<=3),"⚠ URGENT: "&D11&" days left — submit NOW",IF(ISNUMBER(D11),"→ Gather evidence (col M) — "&D11&" days remaining","→ Gather evidence per checklist in col M")))))))) | M11: =IF(H11="","—",IF(OR(ISNUMBER(SEARCH("Fraud",H11)),ISNUMBER(SEARCH("Card Not Present",H11))),"✦ IP address at checkout"&CHAR(10)&"✦ Device ID / fingerprint"&CHAR(10)&"✦ Prior transactions x2"&CHAR(10)&"✦ Delivery confirmation"&CHAR(10)&"✦ Order confirmation"&CHAR(10)&"✦ Customer activity log",IF(OR(ISNUMBER(SEARCH("Not Received",H11)),ISNUMBER(SEARCH("INR",H11))),"✦ Carrier proof of delivery (PDF)"&CHAR(10)&"✦ Tracking number + carrier"&CHAR(10)&"✦ Shipping confirmation email"&CHAR(10)&"✦ Order confirmation",IF(OR(ISNUMBER(SEARCH("Not as Described",H11)),ISNUMBER(SEARCH("SNAD",H11))),"✦ Product listing screenshot"&CHAR(10)&"✦ Order confirmation"&CHAR(10)&"✦ Product photos (as shipped)"&CHAR(10)&"✦ Customer support thread",IF(ISNUMBER(SEARCH("Credit",H11)),"✦ Refund confirmation + timestamp"&CHAR(10)&"✦ Order confirmation"&CHAR(10)&"✦ Customer communication",IF(ISNUMBER(SEARCH("Duplicate",H11)),"✦ Transaction records (single charge)"&CHAR(10)&"✦ Order confirmation"&CHAR(10)&"✦ Processor payment history",IF(ISNUMBER(SEARCH("Subscription",H11)),"✦ Subscription terms at sign-up"&CHAR(10)&"✦ Cancellation policy"&CHAR(10)&"✦ No cancellation received proof",IF(ISNUMBER(SEARCH("Digital",H11)),"✦ Digital delivery confirmation"&CHAR(10)&"✦ Access / usage logs"&CHAR(10)&"✦ Order confirmation","✦ Order confirmation"&CHAR(10)&"✦ Delivery confirmation"&CHAR(10)&"✦ Customer support thread"&CHAR(10)&"✦ Checkout terms screenshot")))))))) | N11: =IF(H11="","—",IF(OR(ISNUMBER(SEARCH("Fraud",H11)),ISNUMBER(SEARCH("Card Not Present",H11))),"T1 — Fraud / Card Not Present",IF(OR(ISNUMBER(SEARCH("Not Received",H11)),ISNUMBER(SEARCH("INR",H11))),"T2 — Item Not Received",IF(OR(ISNUMBER(SEARCH("Not as Described",H11)),ISNUMBER(SEARCH("SNAD",H11))),"T3 — Not as Described",IF(ISNUMBER(SEARCH("Credit",H11)),"T4 — Credit Not Processed",IF(ISNUMBER(SEARCH("Subscription",H11)),"T5 — Subscription Cancelled",IF(ISNUMBER(SEARCH("Digital",H11)),"T6 — Digital Goods Not Delivered",IF(OR(ISNUMBER(SEARCH("Amex",H11)),ISNUMBER(SEARCH("Inquiry",H11))),"T7 — Amex / Inquiry","T7 — General / Other")))))))) | X11: =IF(V11="Win",I11-J11,IF(OR(V11="Accepted",V11="Withdrawn"),-J11,IF(V11="Loss",-I11-J11,""))) | Z11: =IF(B11="","—",IF(AND(A11<>"",B11<>"",C11<>"",E11<>"",F11<>"",G11<>"",H11<>"",K11<>""),"✓ CLEAR","✗ BLOCKED")) | AA11: =IF(B11="","—",IF(K11="Accept","N/A — Accepted",IF(AND(A11<>"",B11<>"",C11<>"",E11<>"",F11<>"",G11<>"",H11<>"",K11<>""),IF(S11="Yes","✓ CLEAR","✗ BLOCKED"),"— Checkpoint 1 first"))) | AB11: =IF(B11="","—",IF(K11="Accept","N/A — Accepted",IF(V11<>"","✓ RESOLVED: "&V11,IF(T11<>"","✓ SUBMITTED",IF(S11="Yes","READY — submit now","✗ BLOCKED")))))
D12: =IF(C12="","",C12-TODAY()) | L12: =IF(B12="","→ Enter dispute details to begin",IF(K12="","→ Run Fight-or-Flight Calculator → enter decision in col K",IF(K12="Accept","✓ Accepted — log in Learning Loop if instructive",IF(V12<>"","✓ Resolved: "&V12&" — complete Learning Loop row",IF(T12<>"","→ Awaiting processor decision — monitor portal",IF(S12="Yes","→ Submit via "&IF(E12="Stripe","Stripe Dashboard → Disputes",IF(E12="Shopify Payments","Shopify Admin → Orders → Chargebacks","PayPal Resolution Centre")),IF(AND(ISNUMBER(D12),D12<=3),"⚠ URGENT: "&D12&" days left — submit NOW",IF(ISNUMBER(D12),"→ Gather evidence (col M) — "&D12&" days remaining","→ Gather evidence per checklist in col M")))))))) | M12: =IF(H12="","—",IF(OR(ISNUMBER(SEARCH("Fraud",H12)),ISNUMBER(SEARCH("Card Not Present",H12))),"✦ IP address at checkout"&CHAR(10)&"✦ Device ID / fingerprint"&CHAR(10)&"✦ Prior transactions x2"&CHAR(10)&"✦ Delivery confirmation"&CHAR(10)&"✦ Order confirmation"&CHAR(10)&"✦ Customer activity log",IF(OR(ISNUMBER(SEARCH("Not Received",H12)),ISNUMBER(SEARCH("INR",H12))),"✦ Carrier proof of delivery (PDF)"&CHAR(10)&"✦ Tracking number + carrier"&CHAR(10)&"✦ Shipping confirmation email"&CHAR(10)&"✦ Order confirmation",IF(OR(ISNUMBER(SEARCH("Not as Described",H12)),ISNUMBER(SEARCH("SNAD",H12))),"✦ Product listing screenshot"&CHAR(10)&"✦ Order confirmation"&CHAR(10)&"✦ Product photos (as shipped)"&CHAR(10)&"✦ Customer support thread",IF(ISNUMBER(SEARCH("Credit",H12)),"✦ Refund confirmation + timestamp"&CHAR(10)&"✦ Order confirmation"&CHAR(10)&"✦ Customer communication",IF(ISNUMBER(SEARCH("Duplicate",H12)),"✦ Transaction records (single charge)"&CHAR(10)&"✦ Order confirmation"&CHAR(10)&"✦ Processor payment history",IF(ISNUMBER(SEARCH("Subscription",H12)),"✦ Subscription terms at sign-up"&CHAR(10)&"✦ Cancellation policy"&CHAR(10)&"✦ No cancellation received proof",IF(ISNUMBER(SEARCH("Digital",H12)),"✦ Digital delivery confirmation"&CHAR(10)&"✦ Access / usage logs"&CHAR(10)&"✦ Order confirmation","✦ Order confirmation"&CHAR(10)&"✦ Delivery confirmation"&CHAR(10)&"✦ Customer support thread"&CHAR(10)&"✦ Checkout terms screenshot")))))))) | N12: =IF(H12="","—",IF(OR(ISNUMBER(SEARCH("Fraud",H12)),ISNUMBER(SEARCH("Card Not Present",H12))),"T1 — Fraud / Card Not Present",IF(OR(ISNUMBER(SEARCH("Not Received",H12)),ISNUMBER(SEARCH("INR",H12))),"T2 — Item Not Received",IF(OR(ISNUMBER(SEARCH("Not as Described",H12)),ISNUMBER(SEARCH("SNAD",H12))),"T3 — Not as Described",IF(ISNUMBER(SEARCH("Credit",H12)),"T4 — Credit Not Processed",IF(ISNUMBER(SEARCH("Subscription",H12)),"T5 — Subscription Cancelled",IF(ISNUMBER(SEARCH("Digital",H12)),"T6 — Digital Goods Not Delivered",IF(OR(ISNUMBER(SEARCH("Amex",H12)),ISNUMBER(SEARCH("Inquiry",H12))),"T7 — Amex / Inquiry","T7 — General / Other")))))))) | X12: =IF(V12="Win",I12-J12,IF(OR(V12="Accepted",V12="Withdrawn"),-J12,IF(V12="Loss",-I12-J12,""))) | Z12: =IF(B12="","—",IF(AND(A12<>"",B12<>"",C12<>"",E12<>"",F12<>"",G12<>"",H12<>"",K12<>""),"✓ CLEAR","✗ BLOCKED")) | AA12: =IF(B12="","—",IF(K12="Accept","N/A — Accepted",IF(AND(A12<>"",B12<>"",C12<>"",E12<>"",F12<>"",G12<>"",H12<>"",K12<>""),IF(S12="Yes","✓ CLEAR","✗ BLOCKED"),"— Checkpoint 1 first"))) | AB12: =IF(B12="","—",IF(K12="Accept","N/A — Accepted",IF(V12<>"","✓ RESOLVED: "&V12,IF(T12<>"","✓ SUBMITTED",IF(S12="Yes","READY — submit now","✗ BLOCKED")))))
D13: =IF(C13="","",C13-TODAY()) | L13: =IF(B13="","→ Enter dispute details to begin",IF(K13="","→ Run Fight-or-Flight Calculator → enter decision in col K",IF(K13="Accept","✓ Accepted — log in Learning Loop if instructive",IF(V13<>"","✓ Resolved: "&V13&" — complete Learning Loop row",IF(T13<>"","→ Awaiting processor decision — monitor portal",IF(S13="Yes","→ Submit via "&IF(E13="Stripe","Stripe Dashboard → Disputes",IF(E13="Shopify Payments","Shopify Admin → Orders → Chargebacks","PayPal Resolution Centre")),IF(AND(ISNUMBER(D13),D13<=3),"⚠ URGENT: "&D13&" days left — submit NOW",IF(ISNUMBER(D13),"→ Gather evidence (col M) — "&D13&" days remaining","→ Gather evidence per checklist in col M")))))))) | M13: =IF(H13="","—",IF(OR(ISNUMBER(SEARCH("Fraud",H13)),ISNUMBER(SEARCH("Card Not Present",H13))),"✦ IP address at checkout"&CHAR(10)&"✦ Device ID / fingerprint"&CHAR(10)&"✦ Prior transactions x2"&CHAR(10)&"✦ Delivery confirmation"&CHAR(10)&"✦ Order confirmation"&CHAR(10)&"✦ Customer activity log",IF(OR(ISNUMBER(SEARCH("Not Received",H13)),ISNUMBER(SEARCH("INR",H13))),"✦ Carrier proof of delivery (PDF)"&CHAR(10)&"✦ Tracking number + carrier"&CHAR(10)&"✦ Shipping confirmation email"&CHAR(10)&"✦ Order confirmation",IF(OR(ISNUMBER(SEARCH("Not as Described",H13)),ISNUMBER(SEARCH("SNAD",H13))),"✦ Product listing screenshot"&CHAR(10)&"✦ Order confirmation"&CHAR(10)&"✦ Product photos (as shipped)"&CHAR(10)&"✦ Customer support thread",IF(ISNUMBER(SEARCH("Credit",H13)),"✦ Refund confirmation + timestamp"&CHAR(10)&"✦ Order confirmation"&CHAR(10)&"✦ Customer communication",IF(ISNUMBER(SEARCH("Duplicate",H13)),"✦ Transaction records (single charge)"&CHAR(10)&"✦ Order confirmation"&CHAR(10)&"✦ Processor payment history",IF(ISNUMBER(SEARCH("Subscription",H13)),"✦ Subscription terms at sign-up"&CHAR(10)&"✦ Cancellation policy"&CHAR(10)&"✦ No cancellation received proof",IF(ISNUMBER(SEARCH("Digital",H13)),"✦ Digital delivery confirmation"&CHAR(10)&"✦ Access / usage logs"&CHAR(10)&"✦ Order confirmation","✦ Order confirmation"&CHAR(10)&"✦ Delivery confirmation"&CHAR(10)&"✦ Customer support thread"&CHAR(10)&"✦ Checkout terms screenshot")))))))) | N13: =IF(H13="","—",IF(OR(ISNUMBER(SEARCH("Fraud",H13)),ISNUMBER(SEARCH("Card Not Present",H13))),"T1 — Fraud / Card Not Present",IF(OR(ISNUMBER(SEARCH("Not Received",H13)),ISNUMBER(SEARCH("INR",H13))),"T2 — Item Not Received",IF(OR(ISNUMBER(SEARCH("Not as Described",H13)),ISNUMBER(SEARCH("SNAD",H13))),"T3 — Not as Described",IF(ISNUMBER(SEARCH("Credit",H13)),"T4 — Credit Not Processed",IF(ISNUMBER(SEARCH("Subscription",H13)),"T5 — Subscription Cancelled",IF(ISNUMBER(SEARCH("Digital",H13)),"T6 — Digital Goods Not Delivered",IF(OR(ISNUMBER(SEARCH("Amex",H13)),ISNUMBER(SEARCH("Inquiry",H13))),"T7 — Amex / Inquiry","T7 — General / Other")))))))) | X13: =IF(V13="Win",I13-J13,IF(OR(V13="Accepted",V13="Withdrawn"),-J13,IF(V13="Loss",-I13-J13,""))) | Z13: =IF(B13="","—",IF(AND(A13<>"",B13<>"",C13<>"",E13<>"",F13<>"",G13<>"",H13<>"",K13<>""),"✓ CLEAR","✗ BLOCKED")) | AA13: =IF(B13="","—",IF(K13="Accept","N/A — Accepted",IF(AND(A13<>"",B13<>"",C13<>"",E13<>"",F13<>"",G13<>"",H13<>"",K13<>""),IF(S13="Yes","✓ CLEAR","✗ BLOCKED"),"— Checkpoint 1 first"))) | AB13: =IF(B13="","—",IF(K13="Accept","N/A — Accepted",IF(V13<>"","✓ RESOLVED: "&V13,IF(T13<>"","✓ SUBMITTED",IF(S13="Yes","READY — submit now","✗ BLOCKED")))))
D14: =IF(C14="","",C14-TODAY()) | L14: =IF(B14="","→ Enter dispute details to begin",IF(K14="","→ Run Fight-or-Flight Calculator → enter decision in col K",IF(K14="Accept","✓ Accepted — log in Learning Loop if instructive",IF(V14<>"","✓ Resolved: "&V14&" — complete Learning Loop row",IF(T14<>"","→ Awaiting processor decision — monitor portal",IF(S14="Yes","→ Submit via "&IF(E14="Stripe","Stripe Dashboard → Disputes",IF(E14="Shopify Payments","Shopify Admin → Orders → Chargebacks","PayPal Resolution Centre")),IF(AND(ISNUMBER(D14),D14<=3),"⚠ URGENT: "&D14&" days left — submit NOW",IF(ISNUMBER(D14),"→ Gather evidence (col M) — "&D14&" days remaining","→ Gather evidence per checklist in col M")))))))) | M14: =IF(H14="","—",IF(OR(ISNUMBER(SEARCH("Fraud",H14)),ISNUMBER(SEARCH("Card Not Present",H14))),"✦ IP address at checkout"&CHAR(10)&"✦ Device ID / fingerprint"&CHAR(10)&"✦ Prior transactions x2"&CHAR(10)&"✦ Delivery confirmation"&CHAR(10)&"✦ Order confirmation"&CHAR(10)&"✦ Customer activity log",IF(OR(ISNUMBER(SEARCH("Not Received",H14)),ISNUMBER(SEARCH("INR",H14))),"✦ Carrier proof of delivery (PDF)"&CHAR(10)&"✦ Tracking number + carrier"&CHAR(10)&"✦ Shipping confirmation email"&CHAR(10)&"✦ Order confirmation",IF(OR(ISNUMBER(SEARCH("Not as Described",H14)),ISNUMBER(SEARCH("SNAD",H14))),"✦ Product listing screenshot"&CHAR(10)&"✦ Order confirmation"&CHAR(10)&"✦ Product photos (as shipped)"&CHAR(10)&"✦ Customer support thread",IF(ISNUMBER(SEARCH("Credit",H14)),"✦ Refund confirmation + timestamp"&CHAR(10)&"✦ Order confirmation"&CHAR(10)&"✦ Customer communication",IF(ISNUMBER(SEARCH("Duplicate",H14)),"✦ Transaction records (single charge)"&CHAR(10)&"✦ Order confirmation"&CHAR(10)&"✦ Processor payment history",IF(ISNUMBER(SEARCH("Subscription",H14)),"✦ Subscription terms at sign-up"&CHAR(10)&"✦ Cancellation policy"&CHAR(10)&"✦ No cancellation received proof",IF(ISNUMBER(SEARCH("Digital",H14)),"✦ Digital delivery confirmation"&CHAR(10)&"✦ Access / usage logs"&CHAR(10)&"✦ Order confirmation","✦ Order confirmation"&CHAR(10)&"✦ Delivery confirmation"&CHAR(10)&"✦ Customer support thread"&CHAR(10)&"✦ Checkout terms screenshot")))))))) | N14: =IF(H14="","—",IF(OR(ISNUMBER(SEARCH("Fraud",H14)),ISNUMBER(SEARCH("Card Not Present",H14))),"T1 — Fraud / Card Not Present",IF(OR(ISNUMBER(SEARCH("Not Received",H14)),ISNUMBER(SEARCH("INR",H14))),"T2 — Item Not Received",IF(OR(ISNUMBER(SEARCH("Not as Described",H14)),ISNUMBER(SEARCH("SNAD",H14))),"T3 — Not as Described",IF(ISNUMBER(SEARCH("Credit",H14)),"T4 — Credit Not Processed",IF(ISNUMBER(SEARCH("Subscription",H14)),"T5 — Subscription Cancelled",IF(ISNUMBER(SEARCH("Digital",H14)),"T6 — Digital Goods Not Delivered",IF(OR(ISNUMBER(SEARCH("Amex",H14)),ISNUMBER(SEARCH("Inquiry",H14))),"T7 — Amex / Inquiry","T7 — General / Other")))))))) | X14: =IF(V14="Win",I14-J14,IF(OR(V14="Accepted",V14="Withdrawn"),-J14,IF(V14="Loss",-I14-J14,""))) | Z14: =IF(B14="","—",IF(AND(A14<>"",B14<>"",C14<>"",E14<>"",F14<>"",G14<>"",H14<>"",K14<>""),"✓ CLEAR","✗ BLOCKED")) | AA14: =IF(B14="","—",IF(K14="Accept","N/A — Accepted",IF(AND(A14<>"",B14<>"",C14<>"",E14<>"",F14<>"",G14<>"",H14<>"",K14<>""),IF(S14="Yes","✓ CLEAR","✗ BLOCKED"),"— Checkpoint 1 first"))) | AB14: =IF(B14="","—",IF(K14="Accept","N/A — Accepted",IF(V14<>"","✓ RESOLVED: "&V14,IF(T14<>"","✓ SUBMITTED",IF(S14="Yes","READY — submit now","✗ BLOCKED")))))
D15: =IF(C15="","",C15-TODAY()) | L15: =IF(B15="","→ Enter dispute details to begin",IF(K15="","→ Run Fight-or-Flight Calculator → enter decision in col K",IF(K15="Accept","✓ Accepted — log in Learning Loop if instructive",IF(V15<>"","✓ Resolved: "&V15&" — complete Learning Loop row",IF(T15<>"","→ Awaiting processor decision — monitor portal",IF(S15="Yes","→ Submit via "&IF(E15="Stripe","Stripe Dashboard → Disputes",IF(E15="Shopify Payments","Shopify Admin → Orders → Chargebacks","PayPal Resolution Centre")),IF(AND(ISNUMBER(D15),D15<=3),"⚠ URGENT: "&D15&" days left — submit NOW",IF(ISNUMBER(D15),"→ Gather evidence (col M) — "&D15&" days remaining","→ Gather evidence per checklist in col M")))))))) | M15: =IF(H15="","—",IF(OR(ISNUMBER(SEARCH("Fraud",H15)),ISNUMBER(SEARCH("Card Not Present",H15))),"✦ IP address at checkout"&CHAR(10)&"✦ Device ID / fingerprint"&CHAR(10)&"✦ Prior transactions x2"&CHAR(10)&"✦ Delivery confirmation"&CHAR(10)&"✦ Order confirmation"&CHAR(10)&"✦ Customer activity log",IF(OR(ISNUMBER(SEARCH("Not Received",H15)),ISNUMBER(SEARCH("INR",H15))),"✦ Carrier proof of delivery (PDF)"&CHAR(10)&"✦ Tracking number + carrier"&CHAR(10)&"✦ Shipping confirmation email"&CHAR(10)&"✦ Order confirmation",IF(OR(ISNUMBER(SEARCH("Not as Described",H15)),ISNUMBER(SEARCH("SNAD",H15))),"✦ Product listing screenshot"&CHAR(10)&"✦ Order confirmation"&CHAR(10)&"✦ Product photos (as shipped)"&CHAR(10)&"✦ Customer support thread",IF(ISNUMBER(SEARCH("Credit",H15)),"✦ Refund confirmation + timestamp"&CHAR(10)&"✦ Order confirmation"&CHAR(10)&"✦ Customer communication",IF(ISNUMBER(SEARCH("Duplicate",H15)),"✦ Transaction records (single charge)"&CHAR(10)&"✦ Order confirmation"&CHAR(10)&"✦ Processor payment history",IF(ISNUMBER(SEARCH("Subscription",H15)),"✦ Subscription terms at sign-up"&CHAR(10)&"✦ Cancellation policy"&CHAR(10)&"✦ No cancellation received proof",IF(ISNUMBER(SEARCH("Digital",H15)),"✦ Digital delivery confirmation"&CHAR(10)&"✦ Access / usage logs"&CHAR(10)&"✦ Order confirmation","✦ Order confirmation"&CHAR(10)&"✦ Delivery confirmation"&CHAR(10)&"✦ Customer support thread"&CHAR(10)&"✦ Checkout terms screenshot")))))))) | N15: =IF(H15="","—",IF(OR(ISNUMBER(SEARCH("Fraud",H15)),ISNUMBER(SEARCH("Card Not Present",H15))),"T1 — Fraud / Card Not Present",IF(OR(ISNUMBER(SEARCH("Not Received",H15)),ISNUMBER(SEARCH("INR",H15))),"T2 — Item Not Received",IF(OR(ISNUMBER(SEARCH("Not as Described",H15)),ISNUMBER(SEARCH("SNAD",H15))),"T3 — Not as Described",IF(ISNUMBER(SEARCH("Credit",H15)),"T4 — Credit Not Processed",IF(ISNUMBER(SEARCH("Subscription",H15)),"T5 — Subscription Cancelled",IF(ISNUMBER(SEARCH("Digital",H15)),"T6 — Digital Goods Not Delivered",IF(OR(ISNUMBER(SEARCH("Amex",H15)),ISNUMBER(SEARCH("Inquiry",H15))),"T7 — Amex / Inquiry","T7 — General / Other")))))))) | X15: =IF(V15="Win",I15-J15,IF(OR(V15="Accepted",V15="Withdrawn"),-J15,IF(V15="Loss",-I15-J15,""))) | Z15: =IF(B15="","—",IF(AND(A15<>"",B15<>"",C15<>"",E15<>"",F15<>"",G15<>"",H15<>"",K15<>""),"✓ CLEAR","✗ BLOCKED")) | AA15: =IF(B15="","—",IF(K15="Accept","N/A — Accepted",IF(AND(A15<>"",B15<>"",C15<>"",E15<>"",F15<>"",G15<>"",H15<>"",K15<>""),IF(S15="Yes","✓ CLEAR","✗ BLOCKED"),"— Checkpoint 1 first"))) | AB15: =IF(B15="","—",IF(K15="Accept","N/A — Accepted",IF(V15<>"","✓ RESOLVED: "&V15,IF(T15<>"","✓ SUBMITTED",IF(S15="Yes","READY — submit now","✗ BLOCKED")))))
D16: =IF(C16="","",C16-TODAY()) | L16: =IF(B16="","→ Enter dispute details to begin",IF(K16="","→ Run Fight-or-Flight Calculator → enter decision in col K",IF(K16="Accept","✓ Accepted — log in Learning Loop if instructive",IF(V16<>"","✓ Resolved: "&V16&" — complete Learning Loop row",IF(T16<>"","→ Awaiting processor decision — monitor portal",IF(S16="Yes","→ Submit via "&IF(E16="Stripe","Stripe Dashboard → Disputes",IF(E16="Shopify Payments","Shopify Admin → Orders → Chargebacks","PayPal Resolution Centre")),IF(AND(ISNUMBER(D16),D16<=3),"⚠ URGENT: "&D16&" days left — submit NOW",IF(ISNUMBER(D16),"→ Gather evidence (col M) — "&D16&" days remaining","→ Gather evidence per checklist in col M")))))))) | M16: =IF(H16="","—",IF(OR(ISNUMBER(SEARCH("Fraud",H16)),ISNUMBER(SEARCH("Card Not Present",H16))),"✦ IP address at checkout"&CHAR(10)&"✦ Device ID / fingerprint"&CHAR(10)&"✦ Prior transactions x2"&CHAR(10)&"✦ Delivery confirmation"&CHAR(10)&"✦ Order confirmation"&CHAR(10)&"✦ Customer activity log",IF(OR(ISNUMBER(SEARCH("Not Received",H16)),ISNUMBER(SEARCH("INR",H16))),"✦ Carrier proof of delivery (PDF)"&CHAR(10)&"✦ Tracking number + carrier"&CHAR(10)&"✦ Shipping confirmation email"&CHAR(10)&"✦ Order confirmation",IF(OR(ISNUMBER(SEARCH("Not as Described",H16)),ISNUMBER(SEARCH("SNAD",H16))),"✦ Product listing screenshot"&CHAR(10)&"✦ Order confirmation"&CHAR(10)&"✦ Product photos (as shipped)"&CHAR(10)&"✦ Customer support thread",IF(ISNUMBER(SEARCH("Credit",H16)),"✦ Refund confirmation + timestamp"&CHAR(10)&"✦ Order confirmation"&CHAR(10)&"✦ Customer communication",IF(ISNUMBER(SEARCH("Duplicate",H16)),"✦ Transaction records (single charge)"&CHAR(10)&"✦ Order confirmation"&CHAR(10)&"✦ Processor payment history",IF(ISNUMBER(SEARCH("Subscription",H16)),"✦ Subscription terms at sign-up"&CHAR(10)&"✦ Cancellation policy"&CHAR(10)&"✦ No cancellation received proof",IF(ISNUMBER(SEARCH("Digital",H16)),"✦ Digital delivery confirmation"&CHAR(10)&"✦ Access / usage logs"&CHAR(10)&"✦ Order confirmation","✦ Order confirmation"&CHAR(10)&"✦ Delivery confirmation"&CHAR(10)&"✦ Customer support thread"&CHAR(10)&"✦ Checkout terms screenshot")))))))) | N16: =IF(H16="","—",IF(OR(ISNUMBER(SEARCH("Fraud",H16)),ISNUMBER(SEARCH("Card Not Present",H16))),"T1 — Fraud / Card Not Present",IF(OR(ISNUMBER(SEARCH("Not Received",H16)),ISNUMBER(SEARCH("INR",H16))),"T2 — Item Not Received",IF(OR(ISNUMBER(SEARCH("Not as Described",H16)),ISNUMBER(SEARCH("SNAD",H16))),"T3 — Not as Described",IF(ISNUMBER(SEARCH("Credit",H16)),"T4 — Credit Not Processed",IF(ISNUMBER(SEARCH("Subscription",H16)),"T5 — Subscription Cancelled",IF(ISNUMBER(SEARCH("Digital",H16)),"T6 — Digital Goods Not Delivered",IF(OR(ISNUMBER(SEARCH("Amex",H16)),ISNUMBER(SEARCH("Inquiry",H16))),"T7 — Amex / Inquiry","T7 — General / Other")))))))) | X16: =IF(V16="Win",I16-J16,IF(OR(V16="Accepted",V16="Withdrawn"),-J16,IF(V16="Loss",-I16-J16,""))) | Z16: =IF(B16="","—",IF(AND(A16<>"",B16<>"",C16<>"",E16<>"",F16<>"",G16<>"",H16<>"",K16<>""),"✓ CLEAR","✗ BLOCKED")) | AA16: =IF(B16="","—",IF(K16="Accept","N/A — Accepted",IF(AND(A16<>"",B16<>"",C16<>"",E16<>"",F16<>"",G16<>"",H16<>"",K16<>""),IF(S16="Yes","✓ CLEAR","✗ BLOCKED"),"— Checkpoint 1 first"))) | AB16: =IF(B16="","—",IF(K16="Accept","N/A — Accepted",IF(V16<>"","✓ RESOLVED: "&V16,IF(T16<>"","✓ SUBMITTED",IF(S16="Yes","READY — submit now","✗ BLOCKED")))))
D17: =IF(C17="","",C17-TODAY()) | L17: =IF(B17="","→ Enter dispute details to begin",IF(K17="","→ Run Fight-or-Flight Calculator → enter decision in col K",IF(K17="Accept","✓ Accepted — log in Learning Loop if instructive",IF(V17<>"","✓ Resolved: "&V17&" — complete Learning Loop row",IF(T17<>"","→ Awaiting processor decision — monitor portal",IF(S17="Yes","→ Submit via "&IF(E17="Stripe","Stripe Dashboard → Disputes",IF(E17="Shopify Payments","Shopify Admin → Orders → Chargebacks","PayPal Resolution Centre")),IF(AND(ISNUMBER(D17),D17<=3),"⚠ URGENT: "&D17&" days left — submit NOW",IF(ISNUMBER(D17),"→ Gather evidence (col M) — "&D17&" days remaining","→ Gather evidence per checklist in col M")))))))) | M17: =IF(H17="","—",IF(OR(ISNUMBER(SEARCH("Fraud",H17)),ISNUMBER(SEARCH("Card Not Present",H17))),"✦ IP address at checkout"&CHAR(10)&"✦ Device ID / fingerprint"&CHAR(10)&"✦ Prior transactions x2"&CHAR(10)&"✦ Delivery confirmation"&CHAR(10)&"✦ Order confirmation"&CHAR(10)&"✦ Customer activity log",IF(OR(ISNUMBER(SEARCH("Not Received",H17)),ISNUMBER(SEARCH("INR",H17))),"✦ Carrier proof of delivery (PDF)"&CHAR(10)&"✦ Tracking number + carrier"&CHAR(10)&"✦ Shipping confirmation email"&CHAR(10)&"✦ Order confirmation",IF(OR(ISNUMBER(SEARCH("Not as Described",H17)),ISNUMBER(SEARCH("SNAD",H17))),"✦ Product listing screenshot"&CHAR(10)&"✦ Order confirmation"&CHAR(10)&"✦ Product photos (as shipped)"&CHAR(10)&"✦ Customer support thread",IF(ISNUMBER(SEARCH("Credit",H17)),"✦ Refund confirmation + timestamp"&CHAR(10)&"✦ Order confirmation"&CHAR(10)&"✦ Customer communication",IF(ISNUMBER(SEARCH("Duplicate",H17)),"✦ Transaction records (single charge)"&CHAR(10)&"✦ Order confirmation"&CHAR(10)&"✦ Processor payment history",IF(ISNUMBER(SEARCH("Subscription",H17)),"✦ Subscription terms at sign-up"&CHAR(10)&"✦ Cancellation policy"&CHAR(10)&"✦ No cancellation received proof",IF(ISNUMBER(SEARCH("Digital",H17)),"✦ Digital delivery confirmation"&CHAR(10)&"✦ Access / usage logs"&CHAR(10)&"✦ Order confirmation","✦ Order confirmation"&CHAR(10)&"✦ Delivery confirmation"&CHAR(10)&"✦ Customer support thread"&CHAR(10)&"✦ Checkout terms screenshot")))))))) | N17: =IF(H17="","—",IF(OR(ISNUMBER(SEARCH("Fraud",H17)),ISNUMBER(SEARCH("Card Not Present",H17))),"T1 — Fraud / Card Not Present",IF(OR(ISNUMBER(SEARCH("Not Received",H17)),ISNUMBER(SEARCH("INR",H17))),"T2 — Item Not Received",IF(OR(ISNUMBER(SEARCH("Not as Described",H17)),ISNUMBER(SEARCH("SNAD",H17))),"T3 — Not as Described",IF(ISNUMBER(SEARCH("Credit",H17)),"T4 — Credit Not Processed",IF(ISNUMBER(SEARCH("Subscription",H17)),"T5 — Subscription Cancelled",IF(ISNUMBER(SEARCH("Digital",H17)),"T6 — Digital Goods Not Delivered",IF(OR(ISNUMBER(SEARCH("Amex",H17)),ISNUMBER(SEARCH("Inquiry",H17))),"T7 — Amex / Inquiry","T7 — General / Other")))))))) | X17: =IF(V17="Win",I17-J17,IF(OR(V17="Accepted",V17="Withdrawn"),-J17,IF(V17="Loss",-I17-J17,""))) | Z17: =IF(B17="","—",IF(AND(A17<>"",B17<>"",C17<>"",E17<>"",F17<>"",G17<>"",H17<>"",K17<>""),"✓ CLEAR","✗ BLOCKED")) | AA17: =IF(B17="","—",IF(K17="Accept","N/A — Accepted",IF(AND(A17<>"",B17<>"",C17<>"",E17<>"",F17<>"",G17<>"",H17<>"",K17<>""),IF(S17="Yes","✓ CLEAR","✗ BLOCKED"),"— Checkpoint 1 first"))) | AB17: =IF(B17="","—",IF(K17="Accept","N/A — Accepted",IF(V17<>"","✓ RESOLVED: "&V17,IF(T17<>"","✓ SUBMITTED",IF(S17="Yes","READY — submit now","✗ BLOCKED")))))
D18: =IF(C18="","",C18-TODAY()) | L18: =IF(B18="","→ Enter dispute details to begin",IF(K18="","→ Run Fight-or-Flight Calculator → enter decision in col K",IF(K18="Accept","✓ Accepted — log in Learning Loop if instructive",IF(V18<>"","✓ Resolved: "&V18&" — complete Learning Loop row",IF(T18<>"","→ Awaiting processor decision — monitor portal",IF(S18="Yes","→ Submit via "&IF(E18="Stripe","Stripe Dashboard → Disputes",IF(E18="Shopify Payments","Shopify Admin → Orders → Chargebacks","PayPal Resolution Centre")),IF(AND(ISNUMBER(D18),D18<=3),"⚠ URGENT: "&D18&" days left — submit NOW",IF(ISNUMBER(D18),"→ Gather evidence (col M) — "&D18&" days remaining","→ Gather evidence per checklist in col M")))))))) | M18: =IF(H18="","—",IF(OR(ISNUMBER(SEARCH("Fraud",H18)),ISNUMBER(SEARCH("Card Not Present",H18))),"✦ IP address at checkout"&CHAR(10)&"✦ Device ID / fingerprint"&CHAR(10)&"✦ Prior transactions x2"&CHAR(10)&"✦ Delivery confirmation"&CHAR(10)&"✦ Order confirmation"&CHAR(10)&"✦ Customer activity log",IF(OR(ISNUMBER(SEARCH("Not Received",H18)),ISNUMBER(SEARCH("INR",H18))),"✦ Carrier proof of delivery (PDF)"&CHAR(10)&"✦ Tracking number + carrier"&CHAR(10)&"✦ Shipping confirmation email"&CHAR(10)&"✦ Order confirmation",IF(OR(ISNUMBER(SEARCH("Not as Described",H18)),ISNUMBER(SEARCH("SNAD",H18))),"✦ Product listing screenshot"&CHAR(10)&"✦ Order confirmation"&CHAR(10)&"✦ Product photos (as shipped)"&CHAR(10)&"✦ Customer support thread",IF(ISNUMBER(SEARCH("Credit",H18)),"✦ Refund confirmation + timestamp"&CHAR(10)&"✦ Order confirmation"&CHAR(10)&"✦ Customer communication",IF(ISNUMBER(SEARCH("Duplicate",H18)),"✦ Transaction records (single charge)"&CHAR(10)&"✦ Order confirmation"&CHAR(10)&"✦ Processor payment history",IF(ISNUMBER(SEARCH("Subscription",H18)),"✦ Subscription terms at sign-up"&CHAR(10)&"✦ Cancellation policy"&CHAR(10)&"✦ No cancellation received proof",IF(ISNUMBER(SEARCH("Digital",H18)),"✦ Digital delivery confirmation"&CHAR(10)&"✦ Access / usage logs"&CHAR(10)&"✦ Order confirmation","✦ Order confirmation"&CHAR(10)&"✦ Delivery confirmation"&CHAR(10)&"✦ Customer support thread"&CHAR(10)&"✦ Checkout terms screenshot")))))))) | N18: =IF(H18="","—",IF(OR(ISNUMBER(SEARCH("Fraud",H18)),ISNUMBER(SEARCH("Card Not Present",H18))),"T1 — Fraud / Card Not Present",IF(OR(ISNUMBER(SEARCH("Not Received",H18)),ISNUMBER(SEARCH("INR",H18))),"T2 — Item Not Received",IF(OR(ISNUMBER(SEARCH("Not as Described",H18)),ISNUMBER(SEARCH("SNAD",H18))),"T3 — Not as Described",IF(ISNUMBER(SEARCH("Credit",H18)),"T4 — Credit Not Processed",IF(ISNUMBER(SEARCH("Subscription",H18)),"T5 — Subscription Cancelled",IF(ISNUMBER(SEARCH("Digital",H18)),"T6 — Digital Goods Not Delivered",IF(OR(ISNUMBER(SEARCH("Amex",H18)),ISNUMBER(SEARCH("Inquiry",H18))),"T7 — Amex / Inquiry","T7 — General / Other")))))))) | X18: =IF(V18="Win",I18-J18,IF(OR(V18="Accepted",V18="Withdrawn"),-J18,IF(V18="Loss",-I18-J18,""))) | Z18: =IF(B18="","—",IF(AND(A18<>"",B18<>"",C18<>"",E18<>"",F18<>"",G18<>"",H18<>"",K18<>""),"✓ CLEAR","✗ BLOCKED")) | AA18: =IF(B18="","—",IF(K18="Accept","N/A — Accepted",IF(AND(A18<>"",B18<>"",C18<>"",E18<>"",F18<>"",G18<>"",H18<>"",K18<>""),IF(S18="Yes","✓ CLEAR","✗ BLOCKED"),"— Checkpoint 1 first"))) | AB18: =IF(B18="","—",IF(K18="Accept","N/A — Accepted",IF(V18<>"","✓ RESOLVED: "&V18,IF(T18<>"","✓ SUBMITTED",IF(S18="Yes","READY — submit now","✗ BLOCKED")))))
... D26: =IF(C26="","",C26-TODAY()) | L26: =IF(B26="","→ Enter dispute details to begin",IF(K26="","→ Run Fight-or-Flight Calculator → enter decision in col K",IF(K26="Accept","✓ Accepted — log in Learning Loop if instructive",IF(V26<>"","✓ Resolved: "&V26&" — complete Learning Loop row",IF(T26<>"","→ Awaiting processor decision — monitor portal",IF(S26="Yes","→ Submit via "&IF(E26="Stripe","Stripe Dashboard → Disputes",IF(E26="Shopify Payments","Shopify Admin → Orders → Chargebacks","PayPal Resolution Centre")),IF(AND(ISNUMBER(D26),D26<=3),"⚠ URGENT: "&D26&" days left — submit NOW",IF(ISNUMBER(D26),"→ Gather evidence (col M) — "&D26&" days remaining","→ Gather evidence per checklist in col M")))))))) | M26: =IF(H26="","—",IF(OR(ISNUMBER(SEARCH("Fraud",H26)),ISNUMBER(SEARCH("Card Not Present",H26))),"✦ IP address at checkout"&CHAR(10)&"✦ Device ID / fingerprint"&CHAR(10)&"✦ Prior transactions x2"&CHAR(10)&"✦ Delivery confirmation"&CHAR(10)&"✦ Order confirmation"&CHAR(10)&"✦ Customer activity log",IF(OR(ISNUMBER(SEARCH("Not Received",H26)),ISNUMBER(SEARCH("INR",H26))),"✦ Carrier proof of delivery (PDF)"&CHAR(10)&"✦ Tracking number + carrier"&CHAR(10)&"✦ Shipping confirmation email"&CHAR(10)&"✦ Order confirmation",IF(OR(ISNUMBER(SEARCH("Not as Described",H26)),ISNUMBER(SEARCH("SNAD",H26))),"✦ Product listing screenshot"&CHAR(10)&"✦ Order confirmation"&CHAR(10)&"✦ Product photos (as shipped)"&CHAR(10)&"✦ Customer support thread",IF(ISNUMBER(SEARCH("Credit",H26)),"✦ Refund confirmation + timestamp"&CHAR(10)&"✦ Order confirmation"&CHAR(10)&"✦ Customer communication",IF(ISNUMBER(SEARCH("Duplicate",H26)),"✦ Transaction records (single charge)"&CHAR(10)&"✦ Order confirmation"&CHAR(10)&"✦ Processor payment history",IF(ISNUMBER(SEARCH("Subscription",H26)),"✦ Subscription terms at sign-up"&CHAR(10)&"✦ Cancellation policy"&CHAR(10)&"✦ No cancellation received proof",IF(ISNUMBER(SEARCH("Digital",H26)),"✦ Digital delivery confirmation"&CHAR(10)&"✦ Access / usage logs"&CHAR(10)&"✦ Order confirmation","✦ Order confirmation"&CHAR(10)&"✦ Delivery confirmation"&CHAR(10)&"✦ Customer support thread"&CHAR(10)&"✦ Checkout terms screenshot")))))))) | N26: =IF(H26="","—",IF(OR(ISNUMBER(SEARCH("Fraud",H26)),ISNUMBER(SEARCH("Card Not Present",H26))),"T1 — Fraud / Card Not Present",IF(OR(ISNUMBER(SEARCH("Not Received",H26)),ISNUMBER(SEARCH("INR",H26))),"T2 — Item Not Received",IF(OR(ISNUMBER(SEARCH("Not as Described",H26)),ISNUMBER(SEARCH("SNAD",H26))),"T3 — Not as Described",IF(ISNUMBER(SEARCH("Credit",H26)),"T4 — Credit Not Processed",IF(ISNUMBER(SEARCH("Subscription",H26)),"T5 — Subscription Cancelled",IF(ISNUMBER(SEARCH("Digital",H26)),"T6 — Digital Goods Not Delivered",IF(OR(ISNUMBER(SEARCH("Amex",H26)),ISNUMBER(SEARCH("Inquiry",H26))),"T7 — Amex / Inquiry","T7 — General / Other")))))))) | X26: =IF(V26="Win",I26-J26,IF(OR(V26="Accepted",V26="Withdrawn"),-J26,IF(V26="Loss",-I26-J26,""))) | Z26: =IF(B26="","—",IF(AND(A26<>"",B26<>"",C26<>"",E26<>"",F26<>"",G26<>"",H26<>"",K26<>""),"✓ CLEAR","✗ BLOCKED")) | AA26: =IF(B26="","—",IF(K26="Accept","N/A — Accepted",IF(AND(A26<>"",B26<>"",C26<>"",E26<>"",F26<>"",G26<>"",H26<>"",K26<>""),IF(S26="Yes","✓ CLEAR","✗ BLOCKED"),"— Checkpoint 1 first"))) | AB26: =IF(B26="","—",IF(K26="Accept","N/A — Accepted",IF(V26<>"","✓ RESOLVED: "&V26,IF(T26<>"","✓ SUBMITTED",IF(S26="Yes","READY — submit now","✗ BLOCKED")))))
A27: TOTALS / SUMMARY | I27: =SUMIF(V6:V26,"<>Accept",I6:I26) | V27: =IF(COUNTIF(V6:V26,"Win")+COUNTIF(V6:V26,"Loss")=0,"—",COUNTIF(V6:V26,"Win")/(COUNTIF(V6:V26,"Win")+COUNTIF(V6:V26,"Loss"))) | X27: =SUM(X6:X26)

Sheet Rate Monitor
A1: CHARGEBACK RATE MONITOR
A2: Track your monthly dispute rate vs. processor thresholds. Update monthly. Watch the trend.
A4: PROCESSOR THRESHOLDS — REFERENCE
A5: PROCESSOR | B5: HARD THRESHOLD | C5: WARNING ZONE | D5: CONSEQUENCE
A6: Stripe | B6: 1.0% | C6: 0.75% | D6: Flag + review. Risk of account termination.
A7: Shopify Payments | B7: 2.0% | C7: 1.5% | D7: Review. Potential payout restriction.
A8: PayPal | B8: ~1.0% | C8: ~0.75% | D8: Account limitations. Varies by history.
A9: Verify current thresholds at your processor portal — these change.
A11: MONTHLY LOG — Update each month
A12: MONTH | B12: PROCESSOR | C12: TRANSACTIONS PROCESSED | D12: CHARGEBACKS RECEIVED | E12: DISPUTE RATE (auto) | F12: THRESHOLD FOR PROCESSOR | G12: STATUS (auto) | H12: CHARGEBACKS TO BREACH (auto) | I12: NOTES
A13: Jan 2025 | B13: Stripe | C13: 3240 | D13: 18 | E13: =IF(C13=0,0,D13/C13) | F13: 0.01 | G13: =IF(OR(F13="",E13=""),"",IF(E13>=F13,"BREACH",IF(E13>=F13*0.75,"WARNING","OK"))) | H13: =IF(OR(F13="",C13=0),"",IF(E13>=F13,"Already breached",ROUND((F13-E13)*C13,0)&" more chargebacks"))
A14: Jan 2025 | B14: Shopify Payments | C14: 890 | D14: 6 | E14: =IF(C14=0,0,D14/C14) | F14: 0.02 | G14: =IF(OR(F14="",E14=""),"",IF(E14>=F14,"BREACH",IF(E14>=F14*0.75,"WARNING","OK"))) | H14: =IF(OR(F14="",C14=0),"",IF(E14>=F14,"Already breached",ROUND((F14-E14)*C14,0)&" more chargebacks"))
A15: Feb 2025 | B15: Stripe | C15: 3510 | D15: 21 | E15: =IF(C15=0,0,D15/C15) | F15: 0.01 | G15: =IF(OR(F15="",E15=""),"",IF(E15>=F15,"BREACH",IF(E15>=F15*0.75,"WARNING","OK"))) | H15: =IF(OR(F15="",C15=0),"",IF(E15>=F15,"Already breached",ROUND((F15-E15)*C15,0)&" more chargebacks"))
A16: Feb 2025 | B16: Shopify Payments | C16: 920 | D16: 8 | E16: =IF(C16=0,0,D16/C16) | F16: 0.02 | G16: =IF(OR(F16="",E16=""),"",IF(E16>=F16,"BREACH",IF(E16>=F16*0.75,"WARNING","OK"))) | H16: =IF(OR(F16="",C16=0),"",IF(E16>=F16,"Already breached",ROUND((F16-E16)*C16,0)&" more chargebacks"))
A17: Mar 2025 | B17: Stripe | C17: 3780 | D17: 29 | E17: =IF(C17=0,0,D17/C17) | F17: 0.01 | G17: =IF(OR(F17="",E17=""),"",IF(E17>=F17,"BREACH",IF(E17>=F17*0.75,"WARNING","OK"))) | H17: =IF(OR(F17="",C17=0),"",IF(E17>=F17,"Already breached",ROUND((F17-E17)*C17,0)&" more chargebacks"))
A18: Mar 2025 | B18: Shopify Payments | C18: 1020 | D18: 11 | E18: =IF(C18=0,0,D18/C18) | F18: 0.02 | G18: =IF(OR(F18="",E18=""),"",IF(E18>=F18,"BREACH",IF(E18>=F18*0.75,"WARNING","OK"))) | H18: =IF(OR(F18="",C18=0),"",IF(E18>=F18,"Already breached",ROUND((F18-E18)*C18,0)&" more chargebacks"))
E19: =IF(C19=0,0,D19/C19) | G19: =IF(OR(F19="",E19=""),"",IF(E19>=F19,"BREACH",IF(E19>=F19*0.75,"WARNING","OK"))) | H19: =IF(OR(F19="",C19=0),"",IF(E19>=F19,"Already breached",ROUND((F19-E19)*C19,0)&" more chargebacks"))
E20: =IF(C20=0,0,D20/C20) | G20: =IF(OR(F20="",E20=""),"",IF(E20>=F20,"BREACH",IF(E20>=F20*0.75,"WARNING","OK"))) | H20: =IF(OR(F20="",C20=0),"",IF(E20>=F20,"Already breached",ROUND((F20-E20)*C20,0)&" more chargebacks"))
E21: =IF(C21=0,0,D21/C21) | G21: =IF(OR(F21="",E21=""),"",IF(E21>=F21,"BREACH",IF(E21>=F21*0.75,"WARNING","OK"))) | H21: =IF(OR(F21="",C21=0),"",IF(E21>=F21,"Already breached",ROUND((F21-E21)*C21,0)&" more chargebacks"))
E22: =IF(C22=0,0,D22/C22) | G22: =IF(OR(F22="",E22=""),"",IF(E22>=F22,"BREACH",IF(E22>=F22*0.75,"WARNING","OK"))) | H22: =IF(OR(F22="",C22=0),"",IF(E22>=F22,"Already breached",ROUND((F22-E22)*C22,0)&" more chargebacks"))
E23: =IF(C23=0,0,D23/C23) | G23: =IF(OR(F23="",E23=""),"",IF(E23>=F23,"BREACH",IF(E23>=F23*0.75,"WARNING","OK"))) | H23: =IF(OR(F23="",C23=0),"",IF(E23>=F23,"Already breached",ROUND((F23-E23)*C23,0)&" more chargebacks"))
E24: =IF(C24=0,0,D24/C24) | G24: =IF(OR(F24="",E24=""),"",IF(E24>=F24,"BREACH",IF(E24>=F24*0.75,"WARNING","OK"))) | H24: =IF(OR(F24="",C24=0),"",IF(E24>=F24,"Already breached",ROUND((F24-E24)*C24,0)&" more chargebacks"))
E25: =IF(C25=0,0,D25/C25) | G25: =IF(OR(F25="",E25=""),"",IF(E25>=F25,"BREACH",IF(E25>=F25*0.75,"WARNING","OK"))) | H25: =IF(OR(F25="",C25=0),"",IF(E25>=F25,"Already breached",ROUND((F25-E25)*C25,0)&" more chargebacks"))
E26: =IF(C26=0,0,D26/C26) | G26: =IF(OR(F26="",E26=""),"",IF(E26>=F26,"BREACH",IF(E26>=F26*0.75,"WARNING","OK"))) | H26: =IF(OR(F26="",C26=0),"",IF(E26>=F26,"Already breached",ROUND((F26-E26)*C26,0)&" more chargebacks"))
E27: =IF(C27=0,0,D27/C27) | G27: =IF(OR(F27="",E27=""),"",IF(E27>=F27,"BREACH",IF(E27>=F27*0.75,"WARNING","OK"))) | H27: =IF(OR(F27="",C27=0),"",IF(E27>=F27,"Already breached",ROUND((F27-E27)*C27,0)&" more chargebacks"))
